2023-02-08 00:23:18,115 INFO    MainThread:22116 [wandb_setup.py:_flush():68] Configure stats pid to 22116
2023-02-08 00:23:18,115 INFO    MainThread:22116 [wandb_setup.py:_flush():68] Loading settings from /home/soulios/.config/wandb/settings
2023-02-08 00:23:18,115 INFO    MainThread:22116 [wandb_setup.py:_flush():68] Loading settings from /home/soulios/git-soulios/deepFPlearn/wandb/settings
2023-02-08 00:23:18,115 INFO    MainThread:22116 [wandb_setup.py:_flush():68] Loading settings from environment variables: {'_require_service': 'True'}
2023-02-08 00:23:18,115 WARNING MainThread:22116 [wandb_setup.py:_flush():68] Could not find program at -m dfpl.__main__
2023-02-08 00:23:18,115 INFO    MainThread:22116 [wandb_setup.py:_flush():68] Inferring run settings from compute environment: {'program_relpath': None, 'program': '-m dfpl.__main__'}
2023-02-08 00:23:18,116 INFO    MainThread:22116 [wandb_init.py:_log_setup():478] Logging user logs to /home/soulios/git-soulios/deepFPlearn/wandb/run-20230208_002318-203fdboc/logs/debug.log
2023-02-08 00:23:18,116 INFO    MainThread:22116 [wandb_init.py:_log_setup():479] Logging internal logs to /home/soulios/git-soulios/deepFPlearn/wandb/run-20230208_002318-203fdboc/logs/debug-internal.log
2023-02-08 00:23:18,116 INFO    MainThread:22116 [wandb_init.py:init():518] calling init triggers
2023-02-08 00:23:18,116 INFO    MainThread:22116 [wandb_init.py:init():521] wandb.init called with sweep_config: {}
config: {}
2023-02-08 00:23:18,116 INFO    MainThread:22116 [wandb_init.py:init():571] starting backend
2023-02-08 00:23:18,116 INFO    MainThread:22116 [wandb_init.py:init():575] setting up manager
2023-02-08 00:23:18,119 INFO    MainThread:22116 [backend.py:_multiprocessing_setup():106] multiprocessing start_methods=fork,spawn,forkserver, using: spawn
2023-02-08 00:23:18,122 INFO    MainThread:22116 [wandb_init.py:init():582] backend started and connected
2023-02-08 00:23:18,127 INFO    MainThread:22116 [wandb_init.py:init():670] updated telemetry
2023-02-08 00:23:18,149 INFO    MainThread:22116 [wandb_init.py:init():710] communicating run to backend with 60.0 second timeout
2023-02-08 00:23:18,696 INFO    MainThread:22116 [wandb_run.py:_on_init():2121] communicating current version
2023-02-08 00:23:18,801 INFO    MainThread:22116 [wandb_run.py:_on_init():2125] got version response upgrade_message: "wandb version 0.13.10 is available!  To upgrade, please run:\n $ pip install wandb --upgrade"

2023-02-08 00:23:18,801 INFO    MainThread:22116 [wandb_init.py:init():758] starting run threads in backend
2023-02-08 00:23:19,484 INFO    MainThread:22116 [wandb_run.py:_console_start():2101] atexit reg
2023-02-08 00:23:19,485 INFO    MainThread:22116 [wandb_run.py:_redirect():1959] redirect: SettingsConsole.WRAP_RAW
2023-02-08 00:23:19,485 INFO    MainThread:22116 [wandb_run.py:_redirect():2024] Wrapping output streams.
2023-02-08 00:23:19,485 INFO    MainThread:22116 [wandb_run.py:_redirect():2046] Redirects installed.
2023-02-08 00:23:19,486 INFO    MainThread:22116 [wandb_init.py:init():798] run started, returning control to user process
2023-02-08 00:23:31,355 ERROR   MainThread:22116 [util.py:get_module():376] Error importing optional module plotly.tools
Traceback (most recent call last):
  File "/home/soulios/anaconda3/envs/dfpl_env/lib/python3.9/site-packages/wandb/util.py", line 337, in import_module_lazy
    return sys.modules[name]
KeyError: 'plotly.tools'

During handling of the above exception, another exception occurred:

Traceback (most recent call last):
  File "/home/soulios/anaconda3/envs/dfpl_env/lib/python3.9/site-packages/wandb/util.py", line 371, in get_module
    return import_module_lazy(name)
  File "/home/soulios/anaconda3/envs/dfpl_env/lib/python3.9/site-packages/wandb/util.py", line 339, in import_module_lazy
    module_spec = importlib.util.find_spec(name)
  File "/home/soulios/anaconda3/envs/dfpl_env/lib/python3.9/importlib/util.py", line 94, in find_spec
    parent = __import__(parent_name, fromlist=['__path__'])
ModuleNotFoundError: No module named 'plotly'
2023-02-08 00:23:37,238 WARNING MsgRouterThr:22116 [router.py:message_loop():77] message_loop has been closed
